<?xml version="1.0" encoding="utf-8"?>
<!-- This URDF was automatically created by SolidWorks to URDF Exporter! Originally created by Stephen Brawner (brawner@gmail.com) 
     Commit Version: 1.6.0-4-g7f85cfe  Build Version: 1.6.7995.38578
     For more information, please see http://wiki.ros.org/sw_urdf_exporter -->
<robot
  name="description_pkg">
  <link
    name="base_link">
    <inertial>
      <origin
        xyz="0.0034114 2.3578E-05 0.037822"
        rpy="0 0 0" />
      <mass
        value="0.51342" />
      <inertia
        ixx="0.0018609"
        ixy="1.3812E-07"
        ixz="9.9607E-18"
        iyy="0.0024947"
        iyz="3.8719E-18"
        izz="0.0043499" />
    </inertial>
    <visual>
      <origin
        xyz="0 0 0"
        rpy="0 0 0" />
      <geometry>
        <mesh
          filename="package://description_pkg/meshes/base_link.STL" />
      </geometry>
      <material
        name="">
        <color
          rgba="0.79216 0.81961 0.93333 1" />
      </material>
    </visual>
    <collision>
      <origin
        xyz="0 0 0"
        rpy="0 0 0" />
      <geometry>
        <mesh
          filename="package://description_pkg/meshes/base_link.STL" />
      </geometry>
    </collision>
  </link>
  <link
    name="right_wheel">
    <inertial>
      <origin
        xyz="-3.9565E-09 0.016121 1.5411E-09"
        rpy="0 0 0" />
      <mass
        value="0.12113" />
      <inertia
        ixx="8.7E-05"
        ixy="1.2167E-11"
        ixz="-9.7666E-14"
        iyy="0.00015319"
        iyz="-4.7353E-12"
        izz="8.7E-05" />
    </inertial>
    <visual>
      <origin
        xyz="0 0 0"
        rpy="0 0 0" />
      <geometry>
        <mesh
          filename="package://description_pkg/meshes/right_wheel.STL" />
      </geometry>
      <material
        name="">
        <color
          rgba="0.50196 0.50196 0.50196 1" />
      </material>
    </visual>
    <collision>
      <origin
        xyz="0 0 0"
        rpy="0 0 0" />
      <geometry>
        <mesh
          filename="package://description_pkg/meshes/right_wheel.STL" />
      </geometry>
    </collision>
  </link>
  <joint
    name="joint_right_wheel"
    type="continuous">
    <origin
      xyz="0.0904581836051767 -0.1095 0.02"
      rpy="0 0 0" />
    <parent
      link="base_link" />
    <child
      link="right_wheel" />
    <axis
      xyz="0 1 0" />
  </joint>
  <link
    name="left_wheel">
    <inertial>
      <origin
        xyz="4.246E-09 -0.016121 6.0085E-13"
        rpy="0 0 0" />
      <mass
        value="0.12113" />
      <inertia
        ixx="8.7E-05"
        ixy="1.3056E-11"
        ixz="1.3227E-13"
        iyy="0.00015319"
        iyz="-1.7583E-15"
        izz="8.7E-05" />
    </inertial>
    <visual>
      <origin
        xyz="0 0 0"
        rpy="0 0 0" />
      <geometry>
        <mesh
          filename="package://description_pkg/meshes/left_wheel.STL" />
      </geometry>
      <material
        name="">
        <color
          rgba="0.50196 0.50196 0.50196 1" />
      </material>
    </visual>
    <collision>
      <origin
        xyz="0 0 0"
        rpy="0 0 0" />
      <geometry>
        <mesh
          filename="package://description_pkg/meshes/left_wheel.STL" />
      </geometry>
    </collision>
  </link>
  <joint
    name="joint_left_wheel"
    type="continuous">
    <origin
      xyz="0.0904581836051742 0.109499999999999 0.0200000000000001"
      rpy="0 0 0" />
    <parent
      link="base_link" />
    <child
      link="left_wheel" />
    <axis
      xyz="0 1 0" />
  </joint>
  <link
    name="lidar">
    <inertial>
      <origin
        xyz="0.0067683 -0.00020768 -0.022438"
        rpy="0 0 0" />
      <mass
        value="0.3304" />
      <inertia
        ixx="0.00061474"
        ixy="-8.0027E-07"
        ixz="0.00015819"
        iyy="0.0009605"
        iyz="-3.096E-06"
        izz="0.0010981" />
    </inertial>
    <visual>
      <origin
        xyz="0 0 0"
        rpy="0 0 0" />
      <geometry>
        <mesh
          filename="package://description_pkg/meshes/lidar.STL" />
      </geometry>
      <material
        name="">
        <color
          rgba="0.29804 0.29804 0.29804 1" />
      </material>
    </visual>
    <collision>
      <origin
        xyz="0 0 0"
        rpy="0 0 0" />
      <geometry>
        <mesh
          filename="package://description_pkg/meshes/lidar.STL" />
      </geometry>
    </collision>
  </link>
  <joint
    name="joint_lidar"
    type="fixed">
    <origin
      xyz="0.0782512924534475 0.000163224895598668 0.1327"
      rpy="0 0 0" />
    <parent
      link="base_link" />
    <child
      link="lidar" />
    <axis
      xyz="0 0 0" />
  </joint>
  
  <!-- <gazebo>
   <plugin name="differential_drive_controller" filename="libgazebo_ros_diff_drive.so">
       <updateRate>30.0</updateRate>
      <commandTopic>cmd_vel</commandTopic>
      <odometryTopic>odom</odometryTopic>
      <odometryFrame>odom</odometryFrame>
      <odometrySource>world</odometrySource>
      <publishOdomTF>true</publishOdomTF>
      <robotBaseFrame>base_link</robotBaseFrame>
      <publishWheelTF>false</publishWheelTF>
      <publishTf>true</publishTf>
      <publishWheelJointState>true</publishWheelJointState>
      <legacyMode>false</legacyMode>
      <updateRate>30</updateRate>
      <leftJoint>joint_left_wheel</leftJoint>
      <rightJoint>joint_right_wheel</rightJoint>
      <wheelSeparation>0.15</wheelSeparation>
      <wheelDiameter>0.085</wheelDiameter>
      <wheelAcceleration>10</wheelAcceleration>
      <wheelTorque>20</wheelTorque>
      <rosDebugLevel>na</rosDebugLevel>
    </plugin>
  </gazebo>
  
     <!- - LIDER - ->
    <gazebo reference="lidar">
        <sensor type="ray" name="head_hokuyo_sensor">
            <pose>0 0 0 0 0 0</pose>
            <visualize>false</visualize>
            <update_rate>40</update_rate>
            <ray>
                <scan>
                    <horizontal>
                        <samples>720</samples>
                        <resolution>1</resolution>
                        <min_angle>-1.570796</min_angle>
                        <max_angle>1.570796</max_angle>
                    </horizontal>
                </scan>
                <range>
                    <min>0.10</min>
                    <max>30.0</max>
                    <resolution>0.01</resolution>
                </range>
                <noise>
                    <type>gaussian</type>
                    <!- - Noise parameters based on published spec for Hokuyo laser
                        achieving "+-30mm" accuracy at range < 10m.  A mean of 0.0m and
                        stddev of 0.01m will put 99.7% of samples within 0.03m of the true
                        reading. - ->
                    <mean>0.0</mean>
                    <stddev>0.01</stddev>
                </noise>
            </ray>
            <plugin name="gazebo_ros_head_hokuyo_controller" filename="libgazebo_ros_laser.so">
                <topicName>/scan</topicName>
                <frameName>lidar</frameName>
            </plugin>
        </sensor>
    </gazebo> -->
  
  
</robot>
